Would you like to try again with a different model or perhaps a different prompt?
INFO: [uagents.registration]: Registration on Almanac API successful
INFO: [uagents.registration]: Almanac contract registration is up to date!
^CINFO: [HF_MANAGEMENT_AGENT]: Shutting down server...
((venv) ) (base) ajitesh@Ajiteshs-MacBook-Pro Cypherpunk % clear
((venv) ) (base) ajitesh@Ajiteshs-MacBook-Pro Cypherpunk % python3 hf_agent.py
INFO:HFManagerAgent:Starting HF Manager Agent on port 8000...
INFO: [HF_MANAGEMENT_AGENT]: Starting agent with address: agent1q04wcekamg3rzekxhnmh776jmkhlkd0s2p5dqpum7nz8ff6jd5yhvwprta3
INFO: [HF_MANAGEMENT_AGENT]: My name is HF_MANAGEMENT_AGENT and my address is agent1q04wcekamg3rzekxhnmh776jmkhlkd0s2p5dqpum7nz8ff6jd5yhvwprta3
INFO: [HF_MANAGEMENT_AGENT]: Agent running on http://localhost:8000
INFO: [HF_MANAGEMENT_AGENT]: Agent inspector available at https://agentverse.ai/inspect/?uri=http%3A//127.0.0.1%3A8000&address=agent1q04wcekamg3rzekxhnmh776jmkhlkd0s2p5dqpum7nz8ff6jd5yhvwprta3
INFO: [HF_MANAGEMENT_AGENT]: Starting server on http://0.0.0.0:8000 (Press CTRL+C to quit)
INFO: [HF_MANAGEMENT_AGENT]: Manifest published successfully: AgentChatProtocol
INFO: [uagents.registration]: Registration on Almanac API successful
INFO: [uagents.registration]: Almanac contract registration is up to date!
INFO:HFManagerAgent:New conversation started with agent1qgl8etxfyrhrdqasrukt6xm23gs9lde2dsdy5zrft59tphf4592m5p082ut
INFO:HFManagerAgent:Received message from agent1qgl8etxfyrhrdqasrukt6xm23gs9lde2dsdy5zrft59tphf4592m5p082ut (Session: agent1qgl8etxfyrhrdqasrukt6xm23gs9lde2dsdy5zrft59tphf4592m5p082ut): Generate a transient response using model '"gpt2"' for prompt: 'history of artificial intelligence in brief using the best hugging face models, use necessary tools and follow main_orchestrator logic' and give me the response.
INFO:HFManagerAgent:Session agent1qgl8etxfyrhrdqasrukt6xm23gs9lde2dsdy5zrft59tphf4592m5p082ut - Turn 1
INFO:HFManagerAgent:LLM requested tool calls: ['run_transient_model']
INFO:HFManagerAgent:Executing tool 'run_transient_model' with args: {'prompt': 'history of artificial intelligence in brief using the best hugging face models, use necessary tools and follow main_orchestrator logic', 'model_id': 'gpt2'}
INFO:HFManagerAgent:Starting transient run for gpt2 with script hf_transient_runner_6ba6265b-938c-4865-898e-1c6518705401.py
WARNING:HFManagerAgent:Transient runner STDERR for gpt2:
Traceback (most recent call last):
File "/Users/ajitesh/Desktop/Cypherpunk/hf_transient_runner_6ba6265b-938c-4865-898e-1c6518705401.py", line 19, in execute_hf_model
pipe = pipeline(task_type, model=model_id, device=device, trust_remote_code=True)
File "/Library/Frameworks/Python.framework/Versions/3.13/lib/python3.13/site-packages/transformers/pipelines/**init**.py", line 948, in pipeline
if task in custom_tasks:
^^^^^^^^^^^^^^^^^^^^
TypeError: unhashable type: 'set'

During handling of the above exception, another exception occurred:

Traceback (most recent call last):
File "/Users/ajitesh/Desktop/Cypherpunk/hf_transient_runner_6ba6265b-938c-4865-898e-1c6518705401.py", line 42, in <module>
execute_hf_model({MODEL_ID}, {PROMPT}, {TASK_TYPE})

```^^^^^^^^^^^^^^^^^^^^^^^^^^^^^^^^^^^
File "/Users/ajitesh/Desktop/Cypherpunk/hf_transient_runner_6ba6265b-938c-4865-898e-1c6518705401.py", line 38, in execute_hf_model
print(json.dumps({"success": False, "error": str(e), "model_id": model_id}))
~~~~~~~~~~^^^^^^^^^^^^^^^^^^^^^^^^^^^^^^^^^^^^^^^^^^^^^^^^^^^^^^^^^^^
File "/Library/Frameworks/Python.framework/Versions/3.13/lib/python3.13/json/**init**.py", line 231, in dumps
return \_default_encoder.encode(obj)
~~~~~~~~~~~~~~~~~~~~~~~^^^^^
File "/Library/Frameworks/Python.framework/Versions/3.13/lib/python3.13/json/encoder.py", line 200, in encode
chunks = self.iterencode(o, \_one_shot=True)
File "/Library/Frameworks/Python.framework/Versions/3.13/lib/python3.13/json/encoder.py", line 261, in iterencode
return \_iterencode(o, 0)
File "/Library/Frameworks/Python.framework/Versions/3.13/lib/python3.13/json/encoder.py", line 180, in default
raise TypeError(f'Object of type {o.**class**.**name**} '
f'is not JSON serializable')
TypeError: Object of type set is not JSON serializable
ERROR:HFManagerAgent:Transient run failed for gpt2: Traceback (most recent call last):
File "/Users/ajitesh/Desktop/Cypherpunk/hf_transient_runner_6ba6265b-938c-4865-898e-1c6518705401.py", line 19, in execute_hf_model
pipe = pipeline(task_type, model=model_id, device=device, trust_remote_code=True)
File "/Library/Frameworks/Python.framework/Versions/3.13/lib/python3.13/site-packages/transformers/pipelines/**init**.py", line 948, in pipeline
if task in custom_tasks:
^^^^^^^^^^^^^^^^^^^^
TypeError: unhashable type: 'set'

During handling of the above exception, another exception occurred:

Traceback (most recent call last):
File "/Users/ajitesh/Desktop/Cypherpunk/hf_transient_runner_6ba6265b-938c-4865-898e-1c6518705401.py", line 42, in <module>
execute_hf_model({MODEL_ID}, {PROMPT}, {TASK_TYPE})
~~~~~~~~~~~~~~~~^^^^^^^^^^^^^^^^^^^^^^^^^^^^^^^^^^^
File "/Users/ajitesh/Desktop/Cypherpunk/hf_transient_runner_6ba6265b-938c-4865-898e-1c6518705401.py", line 38, in execute_hf_model
print(json.dumps({"success": False, "error": str(e), "model_id": model_id}))
~~~~~~~~~~^^^^^^^^^^^^^^^^^^^^^^^^^^^^^^^^^^^^^^^^^^^^^^^^^^^^^^^^^^^
File "/Library/Frameworks/Python.framework/Versions/3.13/lib/python3.13/json/**init**.py", line 231, in dumps
return \_default_encoder.encode(obj)
~~~~~~~~~~~~~~~~~~~~~~~^^^^^
File "/Library/Frameworks/Python.framework/Versions/3.13/lib/python3.13/json/encoder.py", line 200, in encode
chunks = self.iterencode(o, \_one_shot=True)
File "/Library/Frameworks/Python.framework/Versions/3.13/lib/python3.13/json/encoder.py", line 261, in iterencode
return \_iterencode(o, 0)
File "/Library/Frameworks/Python.framework/Versions/3.13/lib/python3.13/json/encoder.py", line 180, in default
raise TypeError(f'Object of type {o.**class**.**name**} '
f'is not JSON serializable')
TypeError: Object of type set is not JSON serializable
INFO:HFManagerAgent:Tool 'run_transient_model' result: {'status': 'error', 'message': 'Traceback (most recent call last):\n File "/Users/ajitesh/Desktop/Cypherpunk/hf_transient_runner_6ba6265b-938c-4865-898e-1c6518705401.py", line 19, in execute_hf_model\n pipe = pipeline(task_type, model=model_id, device=device, trust_remote_code=True)\n File "/Library/Frameworks/Python.framework/Versions/3.13/lib/python3.13/site-packages/transformers/pipelines/**init**.py", line 948, in pipeline\n if task in custom_tasks:\n ^^^^^^^^^^^^^^^^^^^^\nTypeError: unhashable type: \'set\'\n\nDuring handling of the above exception, another exception occurred:\n\nTraceback (most recent call last):\n File "/Users/ajitesh/Desktop/Cypherpunk/hf_transient_runner_6ba6265b-938c-4865-898e-1c6518705401.py", line 42, in <module>\n execute_hf_model({MODEL_ID}, {PROMPT}, {TASK_TYPE})\n ~~~~~~~~~~~~~~~~^^^^^^^^^^^^^^^^^^^^^^^^^^^^^^^^^^^\n File "/Users/ajitesh/Desktop/Cypherpunk/hf_transient_runner_6ba6265b-938c-4865-898e-1c6518705401.py", line 38, in execute_hf_model\n print(json.dumps({"success": False, "error": str(e), "model_id": model_id}))\n ~~~~~~~~~~^^^^^^^^^^^^^^^^^^^^^^^^^^^^^^^^^^^^^^^^^^^^^^^^^^^^^^^^^^^\n File "/Library/Frameworks/Python.framework/Versions/3.13/lib/python3.13/json/**init**.py", line 231, in dumps\n return \_default_encoder.encode(obj)\n ~~~~~~~~~~~~~~~~~~~~~~~^^^^^\n File "/Library/Frameworks/Python.framework/Versions/3.13/lib/python3.13/json/encoder.py", line 200, in encode\n chunks = self.iterencode(o, \_one_shot=True)\n File "/Library/Frameworks/Python.framework/Versions/3.13/lib/python3.13/json/encoder.py", line 261, in iterencode\n return \_iterencode(o, 0)\n File "/Library/Frameworks/Python.framework/Versions/3.13/lib/python3.13/json/encoder.py", line 180, in default\n raise TypeError(f\'Object of type {o.**class**.**name**} \'\n f\'is not JSON serializable\')\nTypeError: Object of type set is not JSON serializable'}
INFO:HFManagerAgent:Session agent1qgl8etxfyrhrdqasrukt6xm23gs9lde2dsdy5zrft59tphf4592m5p082ut - Turn 2
INFO:HFManagerAgent:LLM provided final answer: I'm sorry, there was an error when trying to generate the response using the "gpt2" model. It seems there was a `TypeError` related to JSON serialization within the tool. Would you like to try again or perhaps try a different model?
INFO:HFManagerAgent:Received message from agent1qgl8etxfyrhrdqasrukt6xm23gs9lde2dsdy5zrft59tphf4592m5p082ut (Session: agent1qgl8etxfyrhrdqasrukt6xm23gs9lde2dsdy5zrft59tphf4592m5p082ut): Generate a transient response using model '"gpt2"' for prompt: 'history of artificial intelligence in brief using the best hugging face models, use necessary tools and follow main_orchestrator logic' and give me the response.
INFO:HFManagerAgent:Session agent1qgl8etxfyrhrdqasrukt6xm23gs9lde2dsdy5zrft59tphf4592m5p082ut - Turn 1
INFO:HFManagerAgent:LLM requested tool calls: ['run_transient_model']
INFO:HFManagerAgent:Executing tool 'run_transient_model' with args: {'model_id': 'gpt2', 'prompt': 'history of artificial intelligence in brief using the best hugging face models, use necessary tools and follow main_orchestrator logic'}
INFO:HFManagerAgent:Starting transient run for gpt2 with script hf_transient_runner_86c2a5e8-7d65-4819-8275-d501875186d5.py
WARNING:HFManagerAgent:Transient runner STDERR for gpt2:
Traceback (most recent call last):
File "/Users/ajitesh/Desktop/Cypherpunk/hf_transient_runner_86c2a5e8-7d65-4819-8275-d501875186d5.py", line 19, in execute_hf_model
pipe = pipeline(task_type, model=model_id, device=device, trust_remote_code=True)
File "/Library/Frameworks/Python.framework/Versions/3.13/lib/python3.13/site-packages/transformers/pipelines/**init**.py", line 948, in pipeline
if task in custom_tasks:
^^^^^^^^^^^^^^^^^^^^
TypeError: unhashable type: 'set'

During handling of the above exception, another exception occurred:

Traceback (most recent call last):
File "/Users/ajitesh/Desktop/Cypherpunk/hf_transient_runner_86c2a5e8-7d65-4819-8275-d501875186d5.py", line 42, in <module>
execute_hf_model({MODEL_ID}, {PROMPT}, {TASK_TYPE})
~~~~~~~~~~~~~~~~^^^^^^^^^^^^^^^^^^^^^^^^^^^^^^^^^^^
File "/Users/ajitesh/Desktop/Cypherpunk/hf_transient_runner_86c2a5e8-7d65-4819-8275-d501875186d5.py", line 38, in execute_hf_model
print(json.dumps({"success": False, "error": str(e), "model_id": model_id}))
~~~~~~~~~~^^^^^^^^^^^^^^^^^^^^^^^^^^^^^^^^^^^^^^^^^^^^^^^^^^^^^^^^^^^
File "/Library/Frameworks/Python.framework/Versions/3.13/lib/python3.13/json/**init**.py", line 231, in dumps
return \_default_encoder.encode(obj)
~~~~~~~~~~~~~~~~~~~~~~~^^^^^
File "/Library/Frameworks/Python.framework/Versions/3.13/lib/python3.13/json/encoder.py", line 200, in encode
chunks = self.iterencode(o, \_one_shot=True)
File "/Library/Frameworks/Python.framework/Versions/3.13/lib/python3.13/json/encoder.py", line 261, in iterencode
return \_iterencode(o, 0)
File "/Library/Frameworks/Python.framework/Versions/3.13/lib/python3.13/json/encoder.py", line 180, in default
raise TypeError(f'Object of type {o.**class**.**name**} '
f'is not JSON serializable')
TypeError: Object of type set is not JSON serializable
ERROR:HFManagerAgent:Transient run failed for gpt2: Traceback (most recent call last):
File "/Users/ajitesh/Desktop/Cypherpunk/hf_transient_runner_86c2a5e8-7d65-4819-8275-d501875186d5.py", line 19, in execute_hf_model
pipe = pipeline(task_type, model=model_id, device=device, trust_remote_code=True)
File "/Library/Frameworks/Python.framework/Versions/3.13/lib/python3.13/site-packages/transformers/pipelines/**init**.py", line 948, in pipeline
if task in custom_tasks:
^^^^^^^^^^^^^^^^^^^^
TypeError: unhashable type: 'set'

During handling of the above exception, another exception occurred:

Traceback (most recent call last):
File "/Users/ajitesh/Desktop/Cypherpunk/hf_transient_runner_86c2a5e8-7d65-4819-8275-d501875186d5.py", line 42, in <module>
execute_hf_model({MODEL_ID}, {PROMPT}, {TASK_TYPE})
~~~~~~~~~~~~~~~~^^^^^^^^^^^^^^^^^^^^^^^^^^^^^^^^^^^
File "/Users/ajitesh/Desktop/Cypherpunk/hf_transient_runner_86c2a5e8-7d65-4819-8275-d501875186d5.py", line 38, in execute_hf_model
print(json.dumps({"success": False, "error": str(e), "model_id": model_id}))
~~~~~~~~~~^^^^^^^^^^^^^^^^^^^^^^^^^^^^^^^^^^^^^^^^^^^^^^^^^^^^^^^^^^^
File "/Library/Frameworks/Python.framework/Versions/3.13/lib/python3.13/json/**init**.py", line 231, in dumps
return \_default_encoder.encode(obj)
~~~~~~~~~~~~~~~~~~~~~~~^^^^^
File "/Library/Frameworks/Python.framework/Versions/3.13/lib/python3.13/json/encoder.py", line 200, in encode
chunks = self.iterencode(o, \_one_shot=True)
File "/Library/Frameworks/Python.framework/Versions/3.13/lib/python3.13/json/encoder.py", line 261, in iterencode
return \_iterencode(o, 0)
File "/Library/Frameworks/Python.framework/Versions/3.13/lib/python3.13/json/encoder.py", line 180, in default
raise TypeError(f'Object of type {o.**class**.**name**} '
f'is not JSON serializable')
TypeError: Object of type set is not JSON serializable
INFO:HFManagerAgent:Tool 'run_transient_model' result: {'status': 'error', 'message': 'Traceback (most recent call last):\n File "/Users/ajitesh/Desktop/Cypherpunk/hf_transient_runner_86c2a5e8-7d65-4819-8275-d501875186d5.py", line 19, in execute_hf_model\n pipe = pipeline(task_type, model=model_id, device=device, trust_remote_code=True)\n File "/Library/Frameworks/Python.framework/Versions/3.13/lib/python3.13/site-packages/transformers/pipelines/**init**.py", line 948, in pipeline\n if task in custom_tasks:\n ^^^^^^^^^^^^^^^^^^^^\nTypeError: unhashable type: \'set\'\n\nDuring handling of the above exception, another exception occurred:\n\nTraceback (most recent call last):\n File "/Users/ajitesh/Desktop/Cypherpunk/hf_transient_runner_86c2a5e8-7d65-4819-8275-d501875186d5.py", line 42, in <module>\n execute_hf_model({MODEL_ID}, {PROMPT}, {TASK_TYPE})\n ~~~~~~~~~~~~~~~~^^^^^^^^^^^^^^^^^^^^^^^^^^^^^^^^^^^\n File "/Users/ajitesh/Desktop/Cypherpunk/hf_transient_runner_86c2a5e8-7d65-4819-8275-d501875186d5.py", line 38, in execute_hf_model\n print(json.dumps({"success": False, "error": str(e), "model_id": model_id}))\n ~~~~~~~~~~^^^^^^^^^^^^^^^^^^^^^^^^^^^^^^^^^^^^^^^^^^^^^^^^^^^^^^^^^^^\n File "/Library/Frameworks/Python.framework/Versions/3.13/lib/python3.13/json/**init**.py", line 231, in dumps\n return \_default_encoder.encode(obj)\n ~~~~~~~~~~~~~~~~~~~~~~~^^^^^\n File "/Library/Frameworks/Python.framework/Versions/3.13/lib/python3.13/json/encoder.py", line 200, in encode\n chunks = self.iterencode(o, \_one_shot=True)\n File "/Library/Frameworks/Python.framework/Versions/3.13/lib/python3.13/json/encoder.py", line 261, in iterencode\n return \_iterencode(o, 0)\n File "/Library/Frameworks/Python.framework/Versions/3.13/lib/python3.13/json/encoder.py", line 180, in default\n raise TypeError(f\'Object of type {o.**class**.**name**} \'\n f\'is not JSON serializable\')\nTypeError: Object of type set is not JSON serializable'}
INFO:HFManagerAgent:Session agent1qgl8etxfyrhrdqasrukt6xm23gs9lde2dsdy5zrft59tphf4592m5p082ut - Turn 2
INFO:HFManagerAgent:LLM provided final answer: I apologize, but it seems like we're encountering the same `TypeError` from the tool when trying to run the "gpt2" model in transient mode. This error indicates an issue with the tool's internal handling of data before JSON serialization.

I'm unable to resolve this specific error myself, as it's coming from the underlying tool and not my own understanding. Would you like to try a different approach, or perhaps a different model altogether?
INFO:HFManagerAgent:Received message from agent1qgl8etxfyrhrdqasrukt6xm23gs9lde2dsdy5zrft59tphf4592m5p082ut (Session: agent1qgl8etxfyrhrdqasrukt6xm23gs9lde2dsdy5zrft59tphf4592m5p082ut): Generate a transient response using model '"gpt2"' for prompt: 'history of artificial intelligence in brief using the best hugging face models, use necessary tools and follow main_orchestrator logic' and give me the response.
INFO:HFManagerAgent:Session agent1qgl8etxfyrhrdqasrukt6xm23gs9lde2dsdy5zrft59tphf4592m5p082ut - Turn 1
INFO:HFManagerAgent:LLM requested tool calls: ['run_transient_model']
INFO:HFManagerAgent:Executing tool 'run_transient_model' with args: {'model_id': 'gpt2', 'prompt': 'history of artificial intelligence in brief using the best hugging face models, use necessary tools and follow main_orchestrator logic'}
INFO:HFManagerAgent:Starting transient run for gpt2 with script hf_transient_runner_5bfa950d-a3ba-4840-95c9-e96a8c0be80c.py
WARNING:HFManagerAgent:Transient runner STDERR for gpt2:
Traceback (most recent call last):
File "/Users/ajitesh/Desktop/Cypherpunk/hf_transient_runner_5bfa950d-a3ba-4840-95c9-e96a8c0be80c.py", line 19, in execute_hf_model
pipe = pipeline(task_type, model=model_id, device=device, trust_remote_code=True)
File "/Library/Frameworks/Python.framework/Versions/3.13/lib/python3.13/site-packages/transformers/pipelines/**init**.py", line 948, in pipeline
if task in custom_tasks:
^^^^^^^^^^^^^^^^^^^^
TypeError: unhashable type: 'set'

During handling of the above exception, another exception occurred:

Traceback (most recent call last):
File "/Users/ajitesh/Desktop/Cypherpunk/hf_transient_runner_5bfa950d-a3ba-4840-95c9-e96a8c0be80c.py", line 42, in <module>
execute_hf_model({MODEL_ID}, {PROMPT}, {TASK_TYPE})
~~~~~~~~~~~~~~~~^^^^^^^^^^^^^^^^^^^^^^^^^^^^^^^^^^^
File "/Users/ajitesh/Desktop/Cypherpunk/hf_transient_runner_5bfa950d-a3ba-4840-95c9-e96a8c0be80c.py", line 38, in execute_hf_model
print(json.dumps({"success": False, "error": str(e), "model_id": model_id}))
~~~~~~~~~~^^^^^^^^^^^^^^^^^^^^^^^^^^^^^^^^^^^^^^^^^^^^^^^^^^^^^^^^^^^
File "/Library/Frameworks/Python.framework/Versions/3.13/lib/python3.13/json/**init**.py", line 231, in dumps
return \_default_encoder.encode(obj)
~~~~~~~~~~~~~~~~~~~~~~~^^^^^
File "/Library/Frameworks/Python.framework/Versions/3.13/lib/python3.13/json/encoder.py", line 200, in encode
chunks = self.iterencode(o, \_one_shot=True)
File "/Library/Frameworks/Python.framework/Versions/3.13/lib/python3.13/json/encoder.py", line 261, in iterencode
return \_iterencode(o, 0)
File "/Library/Frameworks/Python.framework/Versions/3.13/lib/python3.13/json/encoder.py", line 180, in default
raise TypeError(f'Object of type {o.**class**.**name**} '
f'is not JSON serializable')
TypeError: Object of type set is not JSON serializable
ERROR:HFManagerAgent:Transient run failed for gpt2: Traceback (most recent call last):
File "/Users/ajitesh/Desktop/Cypherpunk/hf_transient_runner_5bfa950d-a3ba-4840-95c9-e96a8c0be80c.py", line 19, in execute_hf_model
pipe = pipeline(task_type, model=model_id, device=device, trust_remote_code=True)
File "/Library/Frameworks/Python.framework/Versions/3.13/lib/python3.13/site-packages/transformers/pipelines/**init**.py", line 948, in pipeline
if task in custom_tasks:
^^^^^^^^^^^^^^^^^^^^
TypeError: unhashable type: 'set'

During handling of the above exception, another exception occurred:

Traceback (most recent call last):
File "/Users/ajitesh/Desktop/Cypherpunk/hf_transient_runner_5bfa950d-a3ba-4840-95c9-e96a8c0be80c.py", line 42, in <module>
execute_hf_model({MODEL_ID}, {PROMPT}, {TASK_TYPE})
~~~~~~~~~~~~~~~~^^^^^^^^^^^^^^^^^^^^^^^^^^^^^^^^^^^
File "/Users/ajitesh/Desktop/Cypherpunk/hf_transient_runner_5bfa950d-a3ba-4840-95c9-e96a8c0be80c.py", line 38, in execute_hf_model
print(json.dumps({"success": False, "error": str(e), "model_id": model_id}))
~~~~~~~~~~^^^^^^^^^^^^^^^^^^^^^^^^^^^^^^^^^^^^^^^^^^^^^^^^^^^^^^^^^^^
File "/Library/Frameworks/Python.framework/Versions/3.13/lib/python3.13/json/**init**.py", line 231, in dumps
return \_default_encoder.encode(obj)
~~~~~~~~~~~~~~~~~~~~~~~^^^^^
File "/Library/Frameworks/Python.framework/Versions/3.13/lib/python3.13/json/encoder.py", line 200, in encode
chunks = self.iterencode(o, \_one_shot=True)
File "/Library/Frameworks/Python.framework/Versions/3.13/lib/python3.13/json/encoder.py", line 261, in iterencode
return \_iterencode(o, 0)
File "/Library/Frameworks/Python.framework/Versions/3.13/lib/python3.13/json/encoder.py", line 180, in default
raise TypeError(f'Object of type {o.**class**.**name**} '
f'is not JSON serializable')
TypeError: Object of type set is not JSON serializable
INFO:HFManagerAgent:Tool 'run_transient_model' result: {'status': 'error', 'message': 'Traceback (most recent call last):\n File "/Users/ajitesh/Desktop/Cypherpunk/hf_transient_runner_5bfa950d-a3ba-4840-95c9-e96a8c0be80c.py", line 19, in execute_hf_model\n pipe = pipeline(task_type, model=model_id, device=device, trust_remote_code=True)\n File "/Library/Frameworks/Python.framework/Versions/3.13/lib/python3.13/site-packages/transformers/pipelines/**init**.py", line 948, in pipeline\n if task in custom_tasks:\n ^^^^^^^^^^^^^^^^^^^^\nTypeError: unhashable type: \'set\'\n\nDuring handling of the above exception, another exception occurred:\n\nTraceback (most recent call last):\n File "/Users/ajitesh/Desktop/Cypherpunk/hf_transient_runner_5bfa950d-a3ba-4840-95c9-e96a8c0be80c.py", line 42, in <module>\n execute_hf_model({MODEL_ID}, {PROMPT}, {TASK_TYPE})\n ~~~~~~~~~~~~~~~~^^^^^^^^^^^^^^^^^^^^^^^^^^^^^^^^^^^\n File "/Users/ajitesh/Desktop/Cypherpunk/hf_transient_runner_5bfa950d-a3ba-4840-95c9-e96a8c0be80c.py", line 38, in execute_hf_model\n print(json.dumps({"success": False, "error": str(e), "model_id": model_id}))\n ~~~~~~~~~~^^^^^^^^^^^^^^^^^^^^^^^^^^^^^^^^^^^^^^^^^^^^^^^^^^^^^^^^^^^\n File "/Library/Frameworks/Python.framework/Versions/3.13/lib/python3.13/json/**init**.py", line 231, in dumps\n return \_default_encoder.encode(obj)\n ~~~~~~~~~~~~~~~~~~~~~~~^^^^^\n File "/Library/Frameworks/Python.framework/Versions/3.13/lib/python3.13/json/encoder.py", line 200, in encode\n chunks = self.iterencode(o, \_one_shot=True)\n File "/Library/Frameworks/Python.framework/Versions/3.13/lib/python3.13/json/encoder.py", line 261, in iterencode\n return \_iterencode(o, 0)\n File "/Library/Frameworks/Python.framework/Versions/3.13/lib/python3.13/json/encoder.py", line 180, in default\n raise TypeError(f\'Object of type {o.**class**.**name**} \'\n f\'is not JSON serializable\')\nTypeError: Object of type set is not JSON serializable'}
INFO:HFManagerAgent:Session agent1qgl8etxfyrhrdqasrukt6xm23gs9lde2dsdy5zrft59tphf4592m5p082ut - Turn 2
INFO:HFManagerAgent:LLM provided final answer: It seems we're still encountering the same `TypeError` when attempting to use the `run_transient_model` tool with the "gpt2" model. This error indicates a deeper issue within the tool's execution environment concerning how it handles and serializes data.

Since I am an AI model operating through these tools, I cannot directly fix the internal errors of the tools themselves. I can only try to call them with the provided parameters.

Perhaps we could try a different approach if you still want to generate a response about the history of artificial intelligence? Or would you be interested in exploring other functionalities that might not rely on this specific tool call?
INFO:HFManagerAgent:Received message from agent1qgl8etxfyrhrdqasrukt6xm23gs9lde2dsdy5zrft59tphf4592m5p082ut (Session: agent1qgl8etxfyrhrdqasrukt6xm23gs9lde2dsdy5zrft59tphf4592m5p082ut): generate a persistant chat model with HF model_id = '"gpt2"' and task_type = 'auto' and give me the address of new deployed agent.
INFO:HFManagerAgent:Session agent1qgl8etxfyrhrdqasrukt6xm23gs9lde2dsdy5zrft59tphf4592m5p082ut - Turn 1
INFO:HFManagerAgent:LLM requested tool calls: ['run_persistent_model']
INFO:HFManagerAgent:Executing tool 'run_persistent_model' with args: {'task_type': 'auto', 'model_id': 'gpt2'}
INFO:HFManagerAgent:Starting persistent agent for gpt2 on port 8001
INFO:HFManagerAgent:Tool 'run_persistent_model' result: None
INFO:HFManagerAgent:Session agent1qgl8etxfyrhrdqasrukt6xm23gs9lde2dsdy5zrft59tphf4592m5p082ut - Turn 2
INFO:HFManagerAgent:LLM provided final answer: Oh, it looks like there was an unexpected issue when I tried to deploy the persistent model. The tool returned `null` as a result, which isn't very helpful for figuring out what went wrong.

It's possible there's an internal error or a problem with how the deployment process is handled by the tool. I'm unable to get a specific address for a new deployed agent at this moment.

Would you like me to try deploying it again, or perhaps try with a different model or task type?
```
